Workbook

Sheet Gantt
A1: Natural-Language Control of a Sub-250g Drone — Planned vs Actual Gantt (50 Working Days)
A2: Each task has two layers: PLAN (top) and ACTUAL (bottom). Edit the BLUE cells — on Plan rows: Strand, Effort, Start, End, Gate; on Actual rows: hours spent, actual Start and End. Everything else updates itself.
B3: Current project day → yellow box (1–50) | G3: drives the amber in-progress bars and the gold header marker
A5: Ref | B5: Task | C5: Layer | D5: Strand | E5: Effort (hrs) | F5: Start Day | G5: End Day | H5: Dur (days) | I5: Var (days) | J5: Gate | K5: Week 1 | P5: Week 2 | U5: Week 3 | Z5: Week 4 | AE5: Week 5 | AJ5: Week 6 | AO5: Week 7 | AT5: Week 8 | AY5: Week 9 | BD5: Week 10
K6: 1 | L6: 2 | M6: 3 | N6: 4 | O6: 5 | P6: 6 | Q6: 7 | R6: 8 | S6: 9 | T6: 10 | U6: 11 | V6: 12 | W6: 13 | X6: 14 | Y6: 15 | Z6: 16 | AA6: 17 | AB6: 18 | AC6: 19 | AD6: 20 | AE6: 21 | AF6: 22 | AG6: 23 | AH6: 24 | AI6: 25 | AJ6: 26 | AK6: 27 | AL6: 28 | AM6: 29 | AN6: 30 | AO6: 31 | AP6: 32 | AQ6: 33 | AR6: 34 | AS6: 35 | AT6: 36 | AU6: 37 | AV6: 38 | AW6: 39 | AX6: 40 | AY6: 41 | AZ6: 42 | BA6: 43 | BB6: 44 | BC6: 45 | BD6: 46 | BE6: 47 | BF6: 48 | BG6: 49 | BH6: 50
B7: HARDWARE / CONTROL STRAND (critical path)
A8: T1 | B8: Requirements, architecture & BOM | C8: Plan | D8: Summary | E8: =SUMIFS(E10:E17,C10:C17,"Plan") -> 20 | F8: =_xlfn.MINIFS(F10:F17,C10:C17,"Plan") -> 1 | G8: =_xlfn.MAXIFS(G10:G17,C10:C17,"Plan") -> 5 | H8: =G8-F8+1 -> 5
A9: T1 | B9: actual | C9: Actual | D9: Summary | E9: =SUMIFS(E10:E17,C10:C17,"Actual") -> 20 | F9: =IF(COUNTIFS(C10:C17,"Actual",F10:F17,"<>")=0,"",_xlfn.MINIFS(F10:F17,C10:C17,"Actual")) -> 1 | G9: =IF(COUNTIFS(C10:C17,"Actual",G10:G17,"")>0,"",_xlfn.MAXIFS(G10:G17,C10:C17,"Actual")) -> 5 | H9: =IF(OR(F9="",G9=""),"",G9-F9+1) -> 5 | I9: =IF(G9="","",G9-G8) -> 0
A10: T1.1 | B10: Finalise system & software block diagrams | C10: Plan | D10: Critical | E10: 6 | F10: 1 | G10: 2 | H10: =G10-F10+1 -> 2 | K10: =IF(AND($J10<>"",K$6=$G10),"◆","") | L10: =IF(AND($J10<>"",L$6=$G10),"◆","") | M10: =IF(AND($J10<>"",M$6=$G10),"◆","") | N10: =IF(AND($J10<>"",N$6=$G10),"◆","") | O10: =IF(AND($J10<>"",O$6=$G10),"◆","") | P10: =IF(AND($J10<>"",P$6=$G10),"◆","") | Q10: =IF(AND($J10<>"",Q$6=$G10),"◆","") | R10: =IF(AND($J10<>"",R$6=$G10),"◆","") | ... BH10: =IF(AND($J10<>"",BH$6=$G10),"◆","")
A11: T1.1 | B11: actual | C11: Actual | D11: =D10 -> Critical | E11: 6 | F11: 1 | G11: 2 | H11: =IF(OR(F11="",G11=""),"",G11-F11+1) -> 2 | I11: =IF(G11="","",G11-G10) -> 0
A12: T1.2 | B12: Finalise BOM, check budget, place orders | C12: Plan | D12: Critical | E12: 6 | F12: 2 | G12: 3 | H12: =G12-F12+1 -> 2 | K12: =IF(AND($J12<>"",K$6=$G12),"◆","") | L12: =IF(AND($J12<>"",L$6=$G12),"◆","") | M12: =IF(AND($J12<>"",M$6=$G12),"◆","") | N12: =IF(AND($J12<>"",N$6=$G12),"◆","") | O12: =IF(AND($J12<>"",O$6=$G12),"◆","") | P12: =IF(AND($J12<>"",P$6=$G12),"◆","") | Q12: =IF(AND($J12<>"",Q$6=$G12),"◆","") | R12: =IF(AND($J12<>"",R$6=$G12),"◆","") | ... BH12: =IF(AND($J12<>"",BH$6=$G12),"◆","")
A13: T1.2 | B13: actual | C13: Actual | D13: =D12 -> Critical | E13: 6 | F13: 2 | G13: 3 | H13: =IF(OR(F13="",G13=""),"",G13-F13+1) -> 2 | I13: =IF(G13="","",G13-G12) -> 0
A14: T1.3 | B14: Risk assessment form + book indoor test space | C14: Plan | D14: Critical | E14: 4 | F14: 4 | G14: 4 | H14: =G14-F14+1 -> 1 | K14: =IF(AND($J14<>"",K$6=$G14),"◆","") | L14: =IF(AND($J14<>"",L$6=$G14),"◆","") | M14: =IF(AND($J14<>"",M$6=$G14),"◆","") | N14: =IF(AND($J14<>"",N$6=$G14),"◆","") | O14: =IF(AND($J14<>"",O$6=$G14),"◆","") | P14: =IF(AND($J14<>"",P$6=$G14),"◆","") | Q14: =IF(AND($J14<>"",Q$6=$G14),"◆","") | R14: =IF(AND($J14<>"",R$6=$G14),"◆","") | ... BH14: =IF(AND($J14<>"",BH$6=$G14),"◆","")
A15: T1.3 | B15: actual | C15: Actual | D15: =D14 -> Critical | E15: 4 | F15: 4 | G15: 4 | H15: =IF(OR(F15="",G15=""),"",G15-F15+1) -> 1 | I15: =IF(G15="","",G15-G14) -> 0
A16: T1.4 | B16: Supervisor review of Project Outline | C16: Plan | D16: Critical | E16: 4 | F16: 5 | G16: 5 | H16: =G16-F16+1 -> 1 | J16: G1 | K16: =IF(AND($J16<>"",K$6=$G16),"◆","") | L16: =IF(AND($J16<>"",L$6=$G16),"◆","") | M16: =IF(AND($J16<>"",M$6=$G16),"◆","") | N16: =IF(AND($J16<>"",N$6=$G16),"◆","") | O16: =IF(AND($J16<>"",O$6=$G16),"◆","") -> ◆ | P16: =IF(AND($J16<>"",P$6=$G16),"◆","") | Q16: =IF(AND($J16<>"",Q$6=$G16),"◆","") | R16: =IF(AND($J16<>"",R$6=$G16),"◆","") | ... BH16: =IF(AND($J16<>"",BH$6=$G16),"◆","")
A17: T1.4 | B17: actual | C17: Actual | D17: =D16 -> Critical | E17: 4 | F17: 5 | G17: 5 | H17: =IF(OR(F17="",G17=""),"",G17-F17+1) -> 1 | I17: =IF(G17="","",G17-G16) -> 0
A18: T5 | B18: Build & configure drone | C18: Plan | D18: Summary | E18: =SUMIFS(E20:E31,C20:C31,"Plan") -> 30 | F18: =_xlfn.MINIFS(F20:F31,C20:C31,"Plan") -> 6 | G18: =_xlfn.MAXIFS(G20:G31,C20:C31,"Plan") -> 15 | H18: =G18-F18+1 -> 10
A19: T5 | B19: actual | C19: Actual | D19: Summary | E19: =SUMIFS(E20:E31,C20:C31,"Actual") -> 8 | F19: =IF(COUNTIFS(C20:C31,"Actual",F20:F31,"<>")=0,"",_xlfn.MINIFS(F20:F31,C20:C31,"Actual")) -> 6 | G19: =IF(COUNTIFS(C20:C31,"Actual",G20:G31,"")>0,"",_xlfn.MAXIFS(G20:G31,C20:C31,"Actual")) | H19: =IF(OR(F19="",G19=""),"",G19-F19+1) | I19: =IF(G19="","",G19-G18)
A20: T5.1 | B20: Print Synthara remix frame + top deck (Bambu X1, PETG) | C20: Plan | D20: Critical | E20: 4 | F20: 6 | G20: 7 | H20: =G20-F20+1 -> 2 | K20: =IF(AND($J20<>"",K$6=$G20),"◆","") | L20: =IF(AND($J20<>"",L$6=$G20),"◆","") | M20: =IF(AND($J20<>"",M$6=$G20),"◆","") | N20: =IF(AND($J20<>"",N$6=$G20),"◆","") | O20: =IF(AND($J20<>"",O$6=$G20),"◆","") | P20: =IF(AND($J20<>"",P$6=$G20),"◆","") | Q20: =IF(AND($J20<>"",Q$6=$G20),"◆","") | R20: =IF(AND($J20<>"",R$6=$G20),"◆","") | ... BH20: =IF(AND($J20<>"",BH$6=$G20),"◆","")
A21: T5.1 | B21: actual | C21: Actual | D21: =D20 -> Critical | E21: 8 | F21: 6 | G21: 7 | H21: =IF(OR(F21="",G21=""),"",G21-F21+1) -> 2 | I21: =IF(G21="","",G21-G20) -> 0
A22: T5.2 | B22: Bench test stack + motors (props off, Betaflight) | C22: Plan | D22: Critical | E22: 6 | F22: 6 | G22: 8 | H22: =G22-F22+1 -> 3 | K22: =IF(AND($J22<>"",K$6=$G22),"◆","") | L22: =IF(AND($J22<>"",L$6=$G22),"◆","") | M22: =IF(AND($J22<>"",M$6=$G22),"◆","") | N22: =IF(AND($J22<>"",N$6=$G22),"◆","") | O22: =IF(AND($J22<>"",O$6=$G22),"◆","") | P22: =IF(AND($J22<>"",P$6=$G22),"◆","") | Q22: =IF(AND($J22<>"",Q$6=$G22),"◆","") | R22: =IF(AND($J22<>"",R$6=$G22),"◆","") | ... BH22: =IF(AND($J22<>"",BH$6=$G22),"◆","")
A23: T5.2 | B23: actual | C23: Actual | D23: =D22 -> Critical | H23: =IF(OR(F23="",G23=""),"",G23-F23+1) | I23: =IF(G23="","",G23-G22)
A24: T5.3 | B24: Flash ArduPilot (speedybeef4v4) + base config | C24: Plan | D24: Critical | E24: 5 | F24: 9 | G24: 10 | H24: =G24-F24+1 -> 2 | K24: =IF(AND($J24<>"",K$6=$G24),"◆","") | L24: =IF(AND($J24<>"",L$6=$G24),"◆","") | M24: =IF(AND($J24<>"",M$6=$G24),"◆","") | N24: =IF(AND($J24<>"",N$6=$G24),"◆","") | O24: =IF(AND($J24<>"",O$6=$G24),"◆","") | P24: =IF(AND($J24<>"",P$6=$G24),"◆","") | Q24: =IF(AND($J24<>"",Q$6=$G24),"◆","") | R24: =IF(AND($J24<>"",R$6=$G24),"◆","") | ... BH24: =IF(AND($J24<>"",BH$6=$G24),"◆","")
A25: T5.3 | B25: actual | C25: Actual | D25: =D24 -> Critical | H25: =IF(OR(F25="",G25=""),"",G25-F25+1) | I25: =IF(G25="","",G25-G24)
A26: T5.4 | B26: MTF-01 bench test on UART3 (mav-apm) | C26: Plan | D26: Critical | E26: 4 | F26: 10 | G26: 11 | H26: =G26-F26+1 -> 2 | K26: =IF(AND($J26<>"",K$6=$G26),"◆","") | L26: =IF(AND($J26<>"",L$6=$G26),"◆","") | M26: =IF(AND($J26<>"",M$6=$G26),"◆","") | N26: =IF(AND($J26<>"",N$6=$G26),"◆","") | O26: =IF(AND($J26<>"",O$6=$G26),"◆","") | P26: =IF(AND($J26<>"",P$6=$G26),"◆","") | Q26: =IF(AND($J26<>"",Q$6=$G26),"◆","") | R26: =IF(AND($J26<>"",R$6=$G26),"◆","") | ... BH26: =IF(AND($J26<>"",BH$6=$G26),"◆","")
A27: T5.4 | B27: actual | C27: Actual | D27: =D26 -> Critical | H27: =IF(OR(F27="",G27=""),"",G27-F27+1) | I27: =IF(G27="","",G27-G26)
A28: T5.5 | B28: ESP32 DroneBridge flash + MAVLink-over-WiFi test | C28: Plan | D28: Critical | E28: 5 | F28: 11 | G28: 12 | H28: =G28-F28+1 -> 2 | K28: =IF(AND($J28<>"",K$6=$G28),"◆","") | L28: =IF(AND($J28<>"",L$6=$G28),"◆","") | M28: =IF(AND($J28<>"",M$6=$G28),"◆","") | N28: =IF(AND($J28<>"",N$6=$G28),"◆","") | O28: =IF(AND($J28<>"",O$6=$G28),"◆","") | P28: =IF(AND($J28<>"",P$6=$G28),"◆","") | Q28: =IF(AND($J28<>"",Q$6=$G28),"◆","") | R28: =IF(AND($J28<>"",R$6=$G28),"◆","") | ... BH28: =IF(AND($J28<>"",BH$6=$G28),"◆","")
A29: T5.5 | B29: actual | C29: Actual | D29: =D28 -> Critical | H29: =IF(OR(F29="",G29=""),"",G29-F29+1) | I29: =IF(G29="","",G29-G28)
A30: T5.6 | B30: Final assembly; weigh AUW, check balance (CG) | C30: Plan | D30: Critical | E30: 6 | F30: 13 | G30: 15 | H30: =G30-F30+1 -> 3 | K30: =IF(AND($J30<>"",K$6=$G30),"◆","") | L30: =IF(AND($J30<>"",L$6=$G30),"◆","") | M30: =IF(AND($J30<>"",M$6=$G30),"◆","") | N30: =IF(AND($J30<>"",N$6=$G30),"◆","") | O30: =IF(AND($J30<>"",O$6=$G30),"◆","") | P30: =IF(AND($J30<>"",P$6=$G30),"◆","") | Q30: =IF(AND($J30<>"",Q$6=$G30),"◆","") | R30: =IF(AND($J30<>"",R$6=$G30),"◆","") | ... BH30: =IF(AND($J30<>"",BH$6=$G30),"◆","")
A31: T5.6 | B31: actual | C31: Actual | D31: =D30 -> Critical | H31: =IF(OR(F31="",G31=""),"",G31-F31+1) | I31: =IF(G31="","",G31-G30)
A32: T6 | B32: Manual hover testing (laptop/joystick over MAVLink) | C32: Plan | D32: Summary | E32: =SUMIFS(E34:E39,C34:C39,"Plan") -> 15 | F32: =_xlfn.MINIFS(F34:F39,C34:C39,"Plan") -> 16 | G32: =_xlfn.MAXIFS(G34:G39,C34:C39,"Plan") -> 20 | H32: =G32-F32+1 -> 5
A33: T6 | B33: actual | C33: Actual | D33: Summary | E33: =SUMIFS(E34:E39,C34:C39,"Actual") -> 0 | F33: =IF(COUNTIFS(C34:C39,"Actual",F34:F39,"<>")=0,"",_xlfn.MINIFS(F34:F39,C34:C39,"Actual")) | G33: =IF(COUNTIFS(C34:C39,"Actual",G34:G39,"")>0,"",_xlfn.MAXIFS(G34:G39,C34:C39,"Actual")) | H33: =IF(OR(F33="",G33=""),"",G33-F33+1) | I33: =IF(G33="","",G33-G32)
A34: T6.1 | B34: Pre-flight checks: failsafes + disarm kill-switch test | C34: Plan | D34: Critical | E34: 4 | F34: 16 | G34: 16 | H34: =G34-F34+1 -> 1 | K34: =IF(AND($J34<>"",K$6=$G34),"◆","") | L34: =IF(AND($J34<>"",L$6=$G34),"◆","") | M34: =IF(AND($J34<>"",M$6=$G34),"◆","") | N34: =IF(AND($J34<>"",N$6=$G34),"◆","") | O34: =IF(AND($J34<>"",O$6=$G34),"◆","") | P34: =IF(AND($J34<>"",P$6=$G34),"◆","") | Q34: =IF(AND($J34<>"",Q$6=$G34),"◆","") | R34: =IF(AND($J34<>"",R$6=$G34),"◆","") | ... BH34: =IF(AND($J34<>"",BH$6=$G34),"◆","")
A35: T6.1 | B35: actual | C35: Actual | D35: =D34 -> Critical | H35: =IF(OR(F35="",G35=""),"",G35-F35+1) | I35: =IF(G35="","",G35-G34)
A36: T6.2 | B36: Tethered first hover (Stabilize / AltHold) | C36: Plan | D36: Critical | E36: 6 | F36: 17 | G36: 18 | H36: =G36-F36+1 -> 2 | K36: =IF(AND($J36<>"",K$6=$G36),"◆","") | L36: =IF(AND($J36<>"",L$6=$G36),"◆","") | M36: =IF(AND($J36<>"",M$6=$G36),"◆","") | N36: =IF(AND($J36<>"",N$6=$G36),"◆","") | O36: =IF(AND($J36<>"",O$6=$G36),"◆","") | P36: =IF(AND($J36<>"",P$6=$G36),"◆","") | Q36: =IF(AND($J36<>"",Q$6=$G36),"◆","") | R36: =IF(AND($J36<>"",R$6=$G36),"◆","") | ... BH36: =IF(AND($J36<>"",BH$6=$G36),"◆","")
A37: T6.2 | B37: actual | C37: Actual | D37: =D36 -> Critical | H37: =IF(OR(F37="",G37=""),"",G37-F37+1) | I37: =IF(G37="","",G37-G36)
A38: T6.3 | B38: Basic PID tune + log review | C38: Plan | D38: Critical | E38: 5 | F38: 19 | G38: 20 | H38: =G38-F38+1 -> 2 | J38: G2 | K38: =IF(AND($J38<>"",K$6=$G38),"◆","") | L38: =IF(AND($J38<>"",L$6=$G38),"◆","") | M38: =IF(AND($J38<>"",M$6=$G38),"◆","") | N38: =IF(AND($J38<>"",N$6=$G38),"◆","") | O38: =IF(AND($J38<>"",O$6=$G38),"◆","") | P38: =IF(AND($J38<>"",P$6=$G38),"◆","") | Q38: =IF(AND($J38<>"",Q$6=$G38),"◆","") | R38: =IF(AND($J38<>"",R$6=$G38),"◆","") | ... BH38: =IF(AND($J38<>"",BH$6=$G38),"◆","")
A39: T6.3 | B39: actual | C39: Actual | D39: =D38 -> Critical | H39: =IF(OR(F39="",G39=""),"",G39-F39+1) | I39: =IF(G39="","",G39-G38)
A40: T7 | B40: Optical-flow position hold (highest risk) | C40: Plan | D40: Summary | E40: =SUMIFS(E42:E49,C42:C49,"Plan") -> 30 | F40: =_xlfn.MINIFS(F42:F49,C42:C49,"Plan") -> 21 | G40: =_xlfn.MAXIFS(G42:G49,C42:C49,"Plan") -> 30 | H40: =G40-F40+1 -> 10
A41: T7 | B41: actual | C41: Actual | D41: Summary | E41: =SUMIFS(E42:E49,C42:C49,"Actual") -> 0 | F41: =IF(COUNTIFS(C42:C49,"Actual",F42:F49,"<>")=0,"",_xlfn.MINIFS(F42:F49,C42:C49,"Actual")) | G41: =IF(COUNTIFS(C42:C49,"Actual",G42:G49,"")>0,"",_xlfn.MAXIFS(G42:G49,C42:C49,"Actual")) | H41: =IF(OR(F41="",G41=""),"",G41-F41+1) | I41: =IF(G41="","",G41-G40)
...

Sheet Task Details
A1: Task Breakdown — planned vs actual (dates and hours link to the Gantt sheet)
A3: Ref | B3: Parent | C3: Task | D3: Strand | E3: Plan hrs | F3: Plan start | G3: Plan end | H3: Actual hrs | I3: Actual start | J3: Actual end | K3: Var (days) | L3: Status | M3: Measurable outcome (verification) | N3: Depends on / notes
A4: T1.1 | B4: T1 | C4: =Gantt!B10 -> Finalise system & software block diagrams | D4: =Gantt!D10 -> Critical | E4: =IF(Gantt!E10="","",Gantt!E10) -> 6 | F4: =IF(Gantt!F10="","",Gantt!F10) -> 1 | G4: =IF(Gantt!G10="","",Gantt!G10) -> 2 | H4: =IF(Gantt!E11="","",Gantt!E11) -> 6 | I4: =IF(Gantt!F11="","",Gantt!F11) -> 1 | J4: =IF(Gantt!G11="","",Gantt!G11) -> 2 | K4: =IF(Gantt!I11="","",Gantt!I11) -> 0 | L4: =IF(J4<>"",IF(K4>0,"Done — late",IF(K4<0,"Done — early","Done — on time")),IF(I4<>"","In progress","Not started")) -> Done — on time | M4: Figures 1-2 agreed with supervisor
A5: T1.2 | B5: T1 | C5: =Gantt!B12 -> Finalise BOM, check budget, place orders | D5: =Gantt!D12 -> Critical | E5: =IF(Gantt!E12="","",Gantt!E12) -> 6 | F5: =IF(Gantt!F12="","",Gantt!F12) -> 2 | G5: =IF(Gantt!G12="","",Gantt!G12) -> 3 | H5: =IF(Gantt!E13="","",Gantt!E13) -> 6 | I5: =IF(Gantt!F13="","",Gantt!F13) -> 2 | J5: =IF(Gantt!G13="","",Gantt!G13) -> 3 | K5: =IF(Gantt!I13="","",Gantt!I13) -> 0 | L5: =IF(J5<>"",IF(K5>0,"Done — late",IF(K5<0,"Done — early","Done — on time")),IF(I5<>"","In progress","Not started")) -> Done — on time | M5: All parts ordered; cost sheet within budget | N5: Battery + charger still to buy
A6: T1.3 | B6: T1 | C6: =Gantt!B14 -> Risk assessment form + book indoor test space | D6: =Gantt!D14 -> Critical | E6: =IF(Gantt!E14="","",Gantt!E14) -> 4 | F6: =IF(Gantt!F14="","",Gantt!F14) -> 4 | G6: =IF(Gantt!G14="","",Gantt!G14) -> 4 | H6: =IF(Gantt!E15="","",Gantt!E15) -> 4 | I6: =IF(Gantt!F15="","",Gantt!F15) -> 4 | J6: =IF(Gantt!G15="","",Gantt!G15) -> 4 | K6: =IF(Gantt!I15="","",Gantt!I15) -> 0 | L6: =IF(J6<>"",IF(K6>0,"Done — late",IF(K6<0,"Done — early","Done — on time")),IF(I6<>"","In progress","Not started")) -> Done — on time | M6: RA form signed; lab space confirmed
A7: T1.4 | B7: T1 | C7: =Gantt!B16 -> Supervisor review of Project Outline | D7: =Gantt!D16 -> Critical | E7: =IF(Gantt!E16="","",Gantt!E16) -> 4 | F7: =IF(Gantt!F16="","",Gantt!F16) -> 5 | G7: =IF(Gantt!G16="","",Gantt!G16) -> 5 | H7: =IF(Gantt!E17="","",Gantt!E17) -> 4 | I7: =IF(Gantt!F17="","",Gantt!F17) -> 5 | J7: =IF(Gantt!G17="","",Gantt!G17) -> 5 | K7: =IF(Gantt!I17="","",Gantt!I17) -> 0 | L7: =IF(J7<>"",IF(K7>0,"Done — late",IF(K7<0,"Done — early","Done — on time")),IF(I7<>"","In progress","Not started")) -> Done — on time | M7: Outline approved (Gate G1) | N7: T1.1-T1.3
A8: T5.1 | B8: T5 | C8: =Gantt!B20 -> Print Synthara remix frame + top deck (Bambu X1, PETG) | D8: =Gantt!D20 -> Critical | E8: =IF(Gantt!E20="","",Gantt!E20) -> 4 | F8: =IF(Gantt!F20="","",Gantt!F20) -> 6 | G8: =IF(Gantt!G20="","",Gantt!G20) -> 7 | H8: =IF(Gantt!E21="","",Gantt!E21) -> 8 | I8: =IF(Gantt!F21="","",Gantt!F21) -> 6 | J8: =IF(Gantt!G21="","",Gantt!G21) -> 7 | K8: =IF(Gantt!I21="","",Gantt!I21) -> 0 | L8: =IF(J8<>"",IF(K8>0,"Done — late",IF(K8<0,"Done — early","Done — on time")),IF(I8<>"","In progress","Not started")) -> Done — on time | M8: Frame printed, supports cleaned, frame <= 55g | N8: STL files from Drone_CAD/Synthara_Remix
A9: T5.2 | B9: T5 | C9: =Gantt!B22 -> Bench test stack + motors (props off, Betaflight) | D9: =Gantt!D22 -> Critical | E9: =IF(Gantt!E22="","",Gantt!E22) -> 6 | F9: =IF(Gantt!F22="","",Gantt!F22) -> 6 | G9: =IF(Gantt!G22="","",Gantt!G22) -> 8 | H9: =IF(Gantt!E23="","",Gantt!E23) | I9: =IF(Gantt!F23="","",Gantt!F23) | J9: =IF(Gantt!G23="","",Gantt!G23) | K9: =IF(Gantt!I23="","",Gantt!I23) | L9: =IF(J9<>"",IF(K9>0,"Done — late",IF(K9<0,"Done — early","Done — on time")),IF(I9<>"","In progress","Not started")) -> Not started | M9: Smoke test passed; all 4 motors spin, order/direction correct | N9: Bench PSU 11.1V, current-limited
A10: T5.3 | B10: T5 | C10: =Gantt!B24 -> Flash ArduPilot (speedybeef4v4) + base config | D10: =Gantt!D24 -> Critical | E10: =IF(Gantt!E24="","",Gantt!E24) -> 5 | F10: =IF(Gantt!F24="","",Gantt!F24) -> 9 | G10: =IF(Gantt!G24="","",Gantt!G24) -> 10 | H10: =IF(Gantt!E25="","",Gantt!E25) | I10: =IF(Gantt!F25="","",Gantt!F25) | J10: =IF(Gantt!G25="","",Gantt!G25) | K10: =IF(Gantt!I25="","",Gantt!I25) | L10: =IF(J10<>"",IF(K10>0,"Done — late",IF(K10<0,"Done — early","Done — on time")),IF(I10<>"","In progress","Not started")) -> Not started | M10: Quad X, DShot600, accel cal, battery reads within 0.1V | N10: T5.2
A11: T5.4 | B11: T5 | C11: =Gantt!B26 -> MTF-01 bench test on UART3 (mav-apm) | D11: =Gantt!D26 -> Critical | E11: =IF(Gantt!E26="","",Gantt!E26) -> 4 | F11: =IF(Gantt!F26="","",Gantt!F26) -> 10 | G11: =IF(Gantt!G26="","",Gantt!G26) -> 11 | H11: =IF(Gantt!E27="","",Gantt!E27) | I11: =IF(Gantt!F27="","",Gantt!F27) | J11: =IF(Gantt!G27="","",Gantt!G27) | K11: =IF(Gantt!I27="","",Gantt!I27) | L11: =IF(J11<>"",IF(K11>0,"Done — late",IF(K11<0,"Done — early","Done — on time")),IF(I11<>"","In progress","Not started")) -> Not started | M11: Range within a few cm at 0.2/0.5/1 m; flow responds X/Y | N11: T5.3
A12: T5.5 | B12: T5 | C12: =Gantt!B28 -> ESP32 DroneBridge flash + MAVLink-over-WiFi test | D12: =Gantt!D28 -> Critical | E12: =IF(Gantt!E28="","",Gantt!E28) -> 5 | F12: =IF(Gantt!F28="","",Gantt!F28) -> 11 | G12: =IF(Gantt!G28="","",Gantt!G28) -> 12 | H12: =IF(Gantt!E29="","",Gantt!E29) | I12: =IF(Gantt!F29="","",Gantt!F29) | J12: =IF(Gantt!G29="","",Gantt!G29) | K12: =IF(Gantt!I29="","",Gantt!I29) | L12: =IF(J12<>"",IF(K12>0,"Done — late",IF(K12<0,"Done — early","Done — on time")),IF(I12<>"","In progress","Not started")) -> Not started | M12: QGroundControl connects to the FC over WiFi | N12: ESP32 WROOM-32D; avoid 9V pin on VTX port
A13: T5.6 | B13: T5 | C13: =Gantt!B30 -> Final assembly; weigh AUW, check balance (CG) | D13: =Gantt!D30 -> Critical | E13: =IF(Gantt!E30="","",Gantt!E30) -> 6 | F13: =IF(Gantt!F30="","",Gantt!F30) -> 13 | G13: =IF(Gantt!G30="","",Gantt!G30) -> 15 | H13: =IF(Gantt!E31="","",Gantt!E31) | I13: =IF(Gantt!F31="","",Gantt!F31) | J13: =IF(Gantt!G31="","",Gantt!G31) | K13: =IF(Gantt!I31="","",Gantt!I31) | L13: =IF(J13<>"",IF(K13>0,"Done — late",IF(K13<0,"Done — early","Done — on time")),IF(I13<>"","In progress","Not started")) -> Not started | M13: AUW < 250g (target ~203g); CG within 5mm of centre | N13: 3S packs + charger bought; T5.1-T5.5
A14: T6.1 | B14: T6 | C14: =Gantt!B34 -> Pre-flight checks: failsafes + disarm kill-switch test | D14: =Gantt!D34 -> Critical | E14: =IF(Gantt!E34="","",Gantt!E34) -> 4 | F14: =IF(Gantt!F34="","",Gantt!F34) -> 16 | G14: =IF(Gantt!G34="","",Gantt!G34) -> 16 | H14: =IF(Gantt!E35="","",Gantt!E35) | I14: =IF(Gantt!F35="","",Gantt!F35) | J14: =IF(Gantt!G35="","",Gantt!G35) | K14: =IF(Gantt!I35="","",Gantt!I35) | L14: =IF(J14<>"",IF(K14>0,"Done — late",IF(K14<0,"Done — early","Done — on time")),IF(I14<>"","In progress","Not started")) -> Not started | M14: Laptop disarm stops motors instantly; battery failsafe set | N14: T5.6
A15: T6.2 | B15: T6 | C15: =Gantt!B36 -> Tethered first hover (Stabilize / AltHold) | D15: =Gantt!D36 -> Critical | E15: =IF(Gantt!E36="","",Gantt!E36) -> 6 | F15: =IF(Gantt!F36="","",Gantt!F36) -> 17 | G15: =IF(Gantt!G36="","",Gantt!G36) -> 18 | H15: =IF(Gantt!E37="","",Gantt!E37) | I15: =IF(Gantt!F37="","",Gantt!F37) | J15: =IF(Gantt!G37="","",Gantt!G37) | K15: =IF(Gantt!I37="","",Gantt!I37) | L15: =IF(J15<>"",IF(K15>0,"Done — late",IF(K15<0,"Done — early","Done — on time")),IF(I15<>"","In progress","Not started")) -> Not started | M15: 30 s stable tethered hover, no oscillation | N15: Prop guards fitted
A16: T6.3 | B16: T6 | C16: =Gantt!B38 -> Basic PID tune + log review | D16: =Gantt!D38 -> Critical | E16: =IF(Gantt!E38="","",Gantt!E38) -> 5 | F16: =IF(Gantt!F38="","",Gantt!F38) -> 19 | G16: =IF(Gantt!G38="","",Gantt!G38) -> 20 | H16: =IF(Gantt!E39="","",Gantt!E39) | I16: =IF(Gantt!F39="","",Gantt!F39) | J16: =IF(Gantt!G39="","",Gantt!G39) | K16: =IF(Gantt!I39="","",Gantt!I39) | L16: =IF(J16<>"",IF(K16>0,"Done — late",IF(K16<0,"Done — early","Done — on time")),IF(I16<>"","In progress","Not started")) -> Not started | M16: Stable hover recorded on video (Gate G2)
A17: T7.1 | B17: T7 | C17: =Gantt!B42 -> EKF setup for flow + rangefinder (no GPS), sensor offsets | D17: =Gantt!D42 -> Critical | E17: =IF(Gantt!E42="","",Gantt!E42) -> 6 | F17: =IF(Gantt!F42="","",Gantt!F42) -> 21 | G17: =IF(Gantt!G42="","",Gantt!G42) -> 22 | H17: =IF(Gantt!E43="","",Gantt!E43) | I17: =IF(Gantt!F43="","",Gantt!F43) | J17: =IF(Gantt!G43="","",Gantt!G43) | K17: =IF(Gantt!I43="","",Gantt!I43) | L17: =IF(J17<>"",IF(K17>0,"Done — late",IF(K17<0,"Done — early","Done — on time")),IF(I17<>"","In progress","Not started")) -> Not started | M17: EKF healthy on bench; FLOW_POS_X set (~0.041 m) | N17: T5.4
A18: T7.2 | B18: T7 | C18: =Gantt!B44 -> Optical-flow calibration flight + scale factors | D18: =Gantt!D44 -> Critical | E18: =IF(Gantt!E44="","",Gantt!E44) -> 8 | F18: =IF(Gantt!F44="","",Gantt!F44) -> 23 | G18: =IF(Gantt!G44="","",Gantt!G44) -> 25 | H18: =IF(Gantt!E45="","",Gantt!E45) | I18: =IF(Gantt!F45="","",Gantt!F45) | J18: =IF(Gantt!G45="","",Gantt!G45) | K18: =IF(Gantt!I45="","",Gantt!I45) | L18: =IF(J18<>"",IF(K18>0,"Done — late",IF(K18<0,"Done — early","Done — on time")),IF(I18<>"","In progress","Not started")) -> Not started | M18: Flow rates match gyro rates in logs
A19: T7.3 | B19: T7 | C19: =Gantt!B46 -> Loiter position-hold trials + tuning | D19: =Gantt!D46 -> Critical | E19: =IF(Gantt!E46="","",Gantt!E46) -> 12 | F19: =IF(Gantt!F46="","",Gantt!F46) -> 26 | G19: =IF(Gantt!G46="","",Gantt!G46) -> 29 | H19: =IF(Gantt!E47="","",Gantt!E47) | I19: =IF(Gantt!F47="","",Gantt!F47) | J19: =IF(Gantt!G47="","",Gantt!G47) | K19: =IF(Gantt!I47="","",Gantt!I47) | L19: =IF(J19<>"",IF(K19>0,"Done — late",IF(K19<0,"Done — early","Done — on time")),IF(I19<>"","In progress","Not started")) -> Not started | M19: Drift < 0.5 m over 30 s
A20: T7.4 | B20: T7 | C20: =Gantt!B48 -> Repeatability: 5 hold trials, record drift | D20: =Gantt!D48 -> Critical | E20: =IF(Gantt!E48="","",Gantt!E48) -> 4 | F20: =IF(Gantt!F48="","",Gantt!F48) -> 30 | G20: =IF(Gantt!G48="","",Gantt!G48) -> 30 | H20: =IF(Gantt!E49="","",Gantt!E49) | I20: =IF(Gantt!F49="","",Gantt!F49) | J20: =IF(Gantt!G49="","",Gantt!G49) | K20: =IF(Gantt!I49="","",Gantt!I49) | L20: =IF(J20<>"",IF(K20>0,"Done — late",IF(K20<0,"Done — early","Done — on time")),IF(I20<>"","In progress","Not started")) -> Not started | M20: 5/5 trials < 0.5 m drift (Gate G4)
A21: T8.1 | B21: T8 | C21: =Gantt!B52 -> Single voice commands on real drone (tethered) | D21: =Gantt!D52 -> Critical | E21: =IF(Gantt!E52="","",Gantt!E52) -> 6 | F21: =IF(Gantt!F52="","",Gantt!F52) -> 31 | G21: =IF(Gantt!G52="","",Gantt!G52) -> 32 | H21: =IF(Gantt!E53="","",Gantt!E53) | I21: =IF(Gantt!F53="","",Gantt!F53) | J21: =IF(Gantt!G53="","",Gantt!G53) | K21: =IF(Gantt!I53="","",Gantt!I53) | L21: =IF(J21<>"",IF(K21>0,"Done — late",IF(K21<0,"Done — early","Done — on time")),IF(I21<>"","In progress","Not started")) -> Not started | M21: Takeoff / hold / land each work from voice | N21: T4.3, T7.4
A22: T8.2 | B22: T8 | C22: =Gantt!B54 -> Command sequence: take off, move 1 m, land | D22: =Gantt!D54 -> Critical | E22: =IF(Gantt!E54="","",Gantt!E54) -> 9 | F22: =IF(Gantt!F54="","",Gantt!F54) -> 33 | G22: =IF(Gantt!G54="","",Gantt!G54) -> 35 | H22: =IF(Gantt!E55="","",Gantt!E55) | I22: =IF(Gantt!F55="","",Gantt!F55) | J22: =IF(Gantt!G55="","",Gantt!G55) | K22: =IF(Gantt!I55="","",Gantt!I55) | L22: =IF(J22<>"",IF(K22>0,"Done — late",IF(K22<0,"Done — early","Done — on time")),IF(I22<>"","In progress","Not started")) -> Not started | M22: Sequence executed from voice (Gate G5)
A23: T2.1 | B23: T2 | C23: =Gantt!B59 -> Install ArduPilot SITL + QGroundControl / MAVProxy | D23: =Gantt!D59 -> Parallel | E23: =IF(Gantt!E59="","",Gantt!E59) -> 5 | F23: =IF(Gantt!F59="","",Gantt!F59) -> 8 | G23: =IF(Gantt!G59="","",Gantt!G59) -> 8 | H23: =IF(Gantt!E60="","",Gantt!E60) -> 5 | I23: =IF(Gantt!F60="","",Gantt!F60) -> 8 | J23: =IF(Gantt!G60="","",Gantt!G60) -> 8 | K23: =IF(Gantt!I60="","",Gantt!I60) -> 0 | L23: =IF(J23<>"",IF(K23>0,"Done — late",IF(K23<0,"Done — early","Done — on time")),IF(I23<>"","In progress","Not started")) -> Done — on time | M23: Simulated copter arms and flies
A24: T2.2 | B24: T2 | C24: =Gantt!B61 -> pymavlink script: arm, take off, land | D24: =Gantt!D61 -> Parallel | E24: =IF(Gantt!E61="","",Gantt!E61) -> 7 | F24: =IF(Gantt!F61="","",Gantt!F61) -> 3 | G24: =IF(Gantt!G61="","",Gantt!G61) -> 5 | H24: =IF(Gantt!E62="","",Gantt!E62) | I24: =IF(Gantt!F62="","",Gantt!F62) | J24: =IF(Gantt!G62="","",Gantt!G62) | K24: =IF(Gantt!I62="","",Gantt!I62) | L24: =IF(J24<>"",IF(K24>0,"Done — late",IF(K24<0,"Done — early","Done — on time")),IF(I24<>"","In progress","Not started")) -> Not started | M24: Scripted flight completes in SITL
A25: T3.1 | B25: T3 | C25: =Gantt!B65 -> Define command grammar + 30-command test corpus | D25: =Gantt!D65 -> Parallel | E25: =IF(Gantt!E65="","",Gantt!E65) -> 5 | F25: =IF(Gantt!F65="","",Gantt!F65) -> 6 | G25: =IF(Gantt!G65="","",Gantt!G65) -> 7 | H25: =IF(Gantt!E66="","",Gantt!E66) | I25: =IF(Gantt!F66="","",Gantt!F66) | J25: =IF(Gantt!G66="","",Gantt!G66) | K25: =IF(Gantt!I66="","",Gantt!I66) | L25: =IF(J25<>"",IF(K25>0,"Done — late",IF(K25<0,"Done — early","Done — on time")),IF(I25<>"","In progress","Not started")) -> Not started | M25: Corpus file with expected intents and parameters
A26: T3.2 | B26: T3 | C26: =Gantt!B67 -> Whisper vs Vosk: word error rate on corpus | D26: =Gantt!D67 -> Parallel | E26: =IF(Gantt!E67="","",Gantt!E67) -> 8 | F26: =IF(Gantt!F67="","",Gantt!F67) -> 8 | G26: =IF(Gantt!G67="","",Gantt!G67) -> 10 | H26: =IF(Gantt!E68="","",Gantt!E68) | I26: =IF(Gantt!F68="","",Gantt!F68) | J26: =IF(Gantt!G68="","",Gantt!G68) | K26: =IF(Gantt!I68="","",Gantt!I68) | L26: =IF(J26<>"",IF(K26>0,"Done — late",IF(K26<0,"Done — early","Done — on time")),IF(I26<>"","In progress","Not started")) -> Not started | M26: WER table for both engines
A27: T3.3 | B27: T3 | C27: =Gantt!B69 -> Rule-based intent parser (takeoff/move/rotate/hold/land) | D27: =Gantt!D69 -> Parallel | E27: =IF(Gantt!E69="","",Gantt!E69) -> 8 | F27: =IF(Gantt!F69="","",Gantt!F69) -> 11 | G27: =IF(Gantt!G69="","",Gantt!G69) -> 13 | H27: =IF(Gantt!E70="","",Gantt!E70) | I27: =IF(Gantt!F70="","",Gantt!F70) | J27: =IF(Gantt!G70="","",Gantt!G70) | K27: =IF(Gantt!I70="","",Gantt!I70) | L27: =IF(J27<>"",IF(K27>0,"Done — late",IF(K27<0,"Done — early","Done — on time")),IF(I27<>"","In progress","Not started")) -> Not started | M27: >= 90% intent accuracy on typed corpus | N27: T3.1
A28: T3.4 | B28: T3 | C28: =Gantt!B71 -> Live mic -> intent end-to-end test | D28: =Gantt!D71 -> Parallel | E28: =IF(Gantt!E71="","",Gantt!E71) -> 4 | F28: =IF(Gantt!F71="","",Gantt!F71) -> 14 | G28: =IF(Gantt!G71="","",Gantt!G71) -> 15 | H28: =IF(Gantt!E72="","",Gantt!E72) | I28: =IF(Gantt!F72="","",Gantt!F72) | J28: =IF(Gantt!G72="","",Gantt!G72) | K28: =IF(Gantt!I72="","",Gantt!I72) | L28: =IF(J28<>"",IF(K28>0,"Done — late",IF(K28<0,"Done — early","Done — on time")),IF(I28<>"","In progress","Not started")) -> Not started | M28: Accuracy measured on live voice | N28: T3.2, T3.3
A29: T4.1 | B29: T4 | C29: =Gantt!B75 -> Command validator + safety limits | D29: =Gantt!D75 -> Parallel | E29: =IF(Gantt!E75="","",Gantt!E75) -> 6 | F29: =IF(Gantt!F75="","",Gantt!F75) -> 16 | G29: =IF(Gantt!G75="","",Gantt!G75) -> 17 | H29: =IF(Gantt!E76="","",Gantt!E76) | I29: =IF(Gantt!F76="","",Gantt!F76) | J29: =IF(Gantt!G76="","",Gantt!G76) | K29: =IF(Gantt!I76="","",Gantt!I76) | L29: =IF(J29<>"",IF(K29>0,"Done — late",IF(K29<0,"Done — early","Done — on time")),IF(I29<>"","In progress","Not started")) -> Not started | M29: Out-of-range commands rejected in unit tests | N29: T3.3
A30: T4.2 | B30: T4 | C30: =Gantt!B77 -> Intent -> MAVLink guided-mode mapping | D30: =Gantt!D77 -> Parallel | E30: =IF(Gantt!E77="","",Gantt!E77) -> 8 | F30: =IF(Gantt!F77="","",Gantt!F77) -> 17 | G30: =IF(Gantt!G77="","",Gantt!G77) -> 19 | H30: =IF(Gantt!E78="","",Gantt!E78) | I30: =IF(Gantt!F78="","",Gantt!F78) | J30: =IF(Gantt!G78="","",Gantt!G78) | K30: =IF(Gantt!I78="","",Gantt!I78) | L30: =IF(J30<>"",IF(K30>0,"Done — late",IF(K30<0,"Done — early","Done — on time")),IF(I30<>"","In progress","Not started")) -> Not started | M30: Every intent executes correctly in SITL | N30: T2.2
A31: T4.3 | B31: T4 | C31: =Gantt!B79 -> Spoken command drives SITL flight end-to-end | D31: =Gantt!D79 -> Parallel | E31: =IF(Gantt!E79="","",Gantt!E79) -> 4 | F31: =IF(Gantt!F79="","",Gantt!F79) -> 20 | G31: =IF(Gantt!G79="","",Gantt!G79) -> 20 | H31: =IF(Gantt!E80="","",Gantt!E80) | I31: =IF(Gantt!F80="","",Gantt!F80) | J31: =IF(Gantt!G80="","",Gantt!G80) | K31: =IF(Gantt!I80="","",Gantt!I80) | L31: =IF(J31<>"",IF(K31>0,"Done — late",IF(K31<0,"Done — early","Done — on time")),IF(I31<>"","In progress","Not started")) -> Not started | M31: Voice -> simulated flight works (Gate G3)
A32: T9.1 | B32: T9 | C32: =Gantt!B83 -> LLM-based parser behind the same interface | D32: =Gantt!D83 -> Parallel | E32: =IF(Gantt!E83="","",Gantt!E83) -> 8 | F32: =IF(Gantt!F83="","",Gantt!F83) -> 31 | G32: =IF(Gantt!G83="","",Gantt!G83) -> 34 | H32: =IF(Gantt!E84="","",Gantt!E84) | I32: =IF(Gantt!F84="","",Gantt!F84) | J32: =IF(Gantt!G84="","",Gantt!G84) | K32: =IF(Gantt!I84="","",Gantt!I84) | L32: =IF(J32<>"",IF(K32>0,"Done — late",IF(K32<0,"Done — early","Done — on time")),IF(I32<>"","In progress","Not started")) -> Not started | M32: Passes the corpus in the same output format | N32: Ethics decision: own voice vs participants
A33: T9.2 | B33: T9 | C33: =Gantt!B85 -> Compare parsers: accuracy, latency, robustness | D33: =Gantt!D85 -> Parallel | E33: =IF(Gantt!E85="","",Gantt!E85) -> 8 | F33: =IF(Gantt!F85="","",Gantt!F85) -> 35 | G33: =IF(Gantt!G85="","",Gantt!G85) -> 38 | H33: =IF(Gantt!E86="","",Gantt!E86) | I33: =IF(Gantt!F86="","",Gantt!F86) | J33: =IF(Gantt!G86="","",Gantt!G86) | K33: =IF(Gantt!I86="","",Gantt!I86) | L33: =IF(J33<>"",IF(K33>0,"Done — late",IF(K33<0,"Done — early","Done — on time")),IF(I33<>"","In progress","Not started")) -> Not started | M33: Comparison table for both parsers
A34: T9.3 | B34: T9 | C34: =Gantt!B87 -> Results tables + plots for the report | D34: =Gantt!D87 -> Parallel | E34: =IF(Gantt!E87="","",Gantt!E87) -> 4 | F34: =IF(Gantt!F87="","",Gantt!F87) -> 39 | G34: =IF(Gantt!G87="","",Gantt!G87) -> 40 | H34: =IF(Gantt!E88="","",Gantt!E88) | I34: =IF(Gantt!F88="","",Gantt!F88) | J34: =IF(Gantt!G88="","",Gantt!G88) | K34: =IF(Gantt!I88="","",Gantt!I88) | L34: =IF(J34<>"",IF(K34>0,"Done — late",IF(K34<0,"Done — early","Done — on time")),IF(I34<>"","In progress","Not started")) -> Not started | M34: Figures ready for report
A35: T10.1 | B35: T10 | C35: =Gantt!B92 -> Movement-accuracy trials against floor markers | D35: =Gantt!D92 -> Critical | E35: =IF(Gantt!E92="","",Gantt!E92) -> 6 | F35: =IF(Gantt!F92="","",Gantt!F92) -> 36 | G35: =IF(Gantt!G92="","",Gantt!G92) -> 39 | H35: =IF(Gantt!E93="","",Gantt!E93) | I35: =IF(Gantt!F93="","",Gantt!F93) | J35: =IF(Gantt!G93="","",Gantt!G93) | K35: =IF(Gantt!I93="","",Gantt!I93) | L35: =IF(J35<>"",IF(K35>0,"Done — late",IF(K35<0,"Done — early","Done — on time")),IF(I35<>"","In progress","Not started")) -> Not started | M35: Position error table (n >= 5 per command) | N35: T8.2
A36: T10.2 | B36: T10 | C36: =Gantt!B94 -> End-to-end latency measurement (voice -> motion) | D36: =Gantt!D94 -> Critical | E36: =IF(Gantt!E94="","",Gantt!E94) -> 4 | F36: =IF(Gantt!F94="","",Gantt!F94) -> 40 | G36: =IF(Gantt!G94="","",Gantt!G94) -> 41 | H36: =IF(Gantt!E95="","",Gantt!E95) | I36: =IF(Gantt!F95="","",Gantt!F95) | J36: =IF(Gantt!G95="","",Gantt!G95) | K36: =IF(Gantt!I95="","",Gantt!I95) | L36: =IF(J36<>"",IF(K36>0,"Done — late",IF(K36<0,"Done — early","Done — on time")),IF(I36<>"","In progress","Not started")) -> Not started | M36: Latency mean / min / max recorded
A37: T10.3 | B37: T10 | C37: =Gantt!B96 -> Write report: method, results, evaluation | D37: =Gantt!D96 -> Critical | E37: =IF(Gantt!E96="","",Gantt!E96) -> 12 | F37: =IF(Gantt!F96="","",Gantt!F96) -> 42 | G37: =IF(Gantt!G96="","",Gantt!G96) -> 48 | H37: =IF(Gantt!E97="","",Gantt!E97) | I37: =IF(Gantt!F97="","",Gantt!F97) | J37: =IF(Gantt!G97="","",Gantt!G97) | K37: =IF(Gantt!I97="","",Gantt!I97) | L37: =IF(J37<>"",IF(K37>0,"Done — late",IF(K37<0,"Done — early","Done — on time")),IF(I37<>"","In progress","Not started")) -> Not started | M37: Full draft complete
A38: T10.4 | B38: T10 | C38: =Gantt!B98 -> Final review + submission prep | D38: =Gantt!D98 -> Critical | E38: =IF(Gantt!E98="","",Gantt!E98) -> 3 | F38: =IF(Gantt!F98="","",Gantt!F98) -> 49 | G38: =IF(Gantt!G98="","",Gantt!G98) -> 50 | H38: =IF(Gantt!E99="","",Gantt!E99) | I38: =IF(Gantt!F99="","",Gantt!F99) | J38: =IF(Gantt!G99="","",Gantt!G99) | K38: =IF(Gantt!I99="","",Gantt!I99) | L38: =IF(J38<>"",IF(K38>0,"Done — late",IF(K38<0,"Done — early","Done — on time")),IF(I38<>"","In progress","Not started")) -> Not started | M38: Submitted
C39: TOTAL | E39: =SUM(E4:E38) -> 210 | H39: =SUM(H4:H38) -> 33 | L39: =COUNTIF(L4:L38,"Done*")&" of "&ROWS(L4:L38)&" done" -> 6 of 35 done
A41: Green cells mirror the Gantt sheet — edit plan and actual values there. Outcome and notes (blue) are editable here.

Sheet Decision Gates
A1: Decision Gates — planned vs actual day (linked to the Gantt sheet)
A3: Gate | B3: Subtask | C3: Planned day | D3: Actual day | E3: Var (days) | F3: Criterion | G3: Action if not met
A4: G1 | B4: T1.4 | C4: =Gantt!G16 -> 5 | D4: =IF(Gantt!G17="","",Gantt!G17) -> 5 | E4: =IF(D4="","",D4-C4) -> 0 | F4: Outline, BOM and risk assessment approved; lab space confirmed | G4: Revise scope or parts before further spending
A5: G2 | B5: T6.3 | C5: =Gantt!G38 -> 20 | D5: =IF(Gantt!G39="","",Gantt!G39) | E5: =IF(D5="","",D5-C5) | F5: Stable manual hover recorded | G5: Extend tuning; escalate to supervisor
A6: G3 | B6: T4.3 | C6: =Gantt!G79 -> 20 | D6: =IF(Gantt!G80="","",Gantt!G80) | E6: =IF(D6="","",D6-C6) | F6: Voice command drives simulated flight | G6: Hold hardware integration; fix software first
A7: G4 | B7: T7.4 | C7: =Gantt!G48 -> 30 | D7: =IF(Gantt!G49="","",Gantt!G49) | E7: =IF(D7="","",D7-C7) | F7: Hands-off position hold < 0.5 m drift, 5/5 trials (pivotal) | G7: Demonstrate T8 in simulation; report hardware hold as a documented limitation
A8: G5 | B8: T8.2 | C8: =Gantt!G54 -> 35 | D8: =IF(Gantt!G55="","",Gantt!G55) | E8: =IF(D8="","",D8-C8) | F8: Voice sequence executes on the real drone | G8: Base evaluation on simulation results
A10: Slack: | B10: The software strand is free from day 21 to day 30, so it can absorb slippage in the high-risk position-hold work (T7). Reporting runs to day 50, leaving roughly ten working days of contingency after the voice-control milestone (G5, day 35). Watch the Var column: a positive number on a critical-path task pushes everything after it.
